[wsgi:error] ERROR:app:Exception on /view_answer [POST]
[wsgi:error] Traceback (most recent call last):
[wsgi:error]   File "/usr/local/venv/py3/lib/python3.10/site-packages/sqlalchemy/engine/base.py", line 1967, in _exec_single_context
[wsgi:error]     self.dialect.do_execute(    
[wsgi:error]   File "/usr/local/venv/py3/lib/python3.10/site-packages/sqlalchemy/engine/default.py", line 924, in do_execute
[wsgi:error]     cursor.execute(statement, parameters)
[wsgi:error] sqlite3.OperationalError: attempt to write a readonly database
[wsgi:error] ...
[wsgi:error] The above exception was the direct cause of the following exception:
[wsgi:error]   File "/usr/local/venv/py3/lib/python3.10/site-packages/sqlalchemy/engine/default.py", line 924, in do_execute
[wsgi:error]     cursor.execute(statement, parameters)
[wsgi:error] sqlalchemy.exc.OperationalError: (sqlite3.OperationalError) attempt to write a readonly database
[wsgi:error] [SQL: INSERT INTO ratings (user_id, pun_id, rating, avg_user_rating, avg_pun_rating) VALUES (?, ?, ?, ?, ?)]
[wsgi:error] [parameters: (1, 1, 'Sigh', 1.0, 2.0)]
[wsgi:error] (Background on this error at: https://sqlalche.me/e/20/e3q8)


ERROR:app:Exception on /view_answer [POST]
Traceback (most recent call last):
  File "/usr/local/venv/py3/lib/python3.10/site-packages/flask/app.py", line 1473, in wsgi_app        
    response = self.full_dispatch_request()
...
  File "/usr/local/venv/py3/lib/python3.10/site-packages/flask_login/utils.py", line 290, in decorated_view
    return current_app.ensure_sync(func)(*args, **kwargs)
  File "/var/www/webApp/app.py", line 396, in view_answer
    return render_template(
  File "/usr/local/venv/py3/lib/python3.10/site-packages/flask/templating.py", line 149, in render_template
...
    return loader.get_source(environment, template)
  File "/usr/local/venv/py3/lib/python3.10/site-packages/jinja2/loaders.py", line 210, in get_source  
    contents = f.read()
  File "/usr/lib/python3.10/codecs.py", line 322, in decode
    (result, consumed) = self._buffer_decode(data, self.errors, final)
UnicodeDecodeError: 'utf-8' codec can't decode byte 0xed in position 296: invalid continuation byte 